Workbook

Sheet Synthèse
B2: Chiffrage détaillé — Plateforme ALTERRA
B3: Mise en place système de gestion des travailleurs temporaires — Airtable + Jotform
B5: Version | C5: v1 — chiffrage optimisé
B6: Date | C6: 28 avril 2026
B7: Périmètre | C7: Pilote 1 site, ~50 travailleurs, 3-5 utilisateurs Admin/Chef de Site
B9: Hypothèse de calcul
B10: TJM (Taux Journalier Moyen) | C10: 0 | E10: à renseigner
B12: Synthèse par phase
B13: Phase | C13: Jours-homme | D13: % du total | E13: Coût (TJM × j-h)
B14: 1. Cadrage et conception | C14: 4 | D14: =C14/$C$21 -> 0.14285714 | E14: =C14*$C$10 -> 0
B15: 2. Configuration Airtable | C15: 7 | D15: =C15/$C$21 -> 0.25 | E15: =C15*$C$10 -> 0
B16: 3. Jotform et intégration | C16: 5 | D16: =C16/$C$21 -> 0.17857143 | E16: =C16*$C$10 -> 0
B17: 4. Données initiales et comptes utilisateurs | C17: 2 | D17: =C17/$C$21 -> 0.071428571 | E17: =C17*$C$10 -> 0
B18: 5. Tests et recette | C18: 4 | D18: =C18/$C$21 -> 0.14285714 | E18: =C18*$C$10 -> 0
B19: 6. Formation et déploiement | C19: 3 | D19: =C19/$C$21 -> 0.10714286 | E19: =C19*$C$10 -> 0
B20: 7. Hypercare | C20: 3 | D20: =C20/$C$21 -> 0.10714286 | E20: =C20*$C$10 -> 0
B21: TOTAL | C21: =SUM(C14:C20) -> 28 | D21: =SUM(D14:D20) -> 1 | E21: =C21*C10 -> 0
B23: Le détail tâche par tâche est disponible dans l'onglet « Détail ». Hypothèses, périmètre et exclusions dans l'onglet « Hypothèses ». Coûts récurrents Airtable et Jotform dans l'onglet « Licences ».
B25: Comparatif vs proposition initiale NextA
B26: Élément | C26: NextA initial | D26: Optimisé | E26: Écart
B27: Total jours-homme | C27: 24 j | D27: 28 j | E27: +4 j
B28: Conception | C28: 5 j | D28: 4 j | E28: -1 j
B29: Développement / Configuration | C29: 10 j | D29: 12 j | E29: +2 j
B30: Tests et formation | C30: 4 j | D30: 4 j | E30: =
B31: Données initiales et comptes | C31: 0 j (non couvert) | D31: 2 j | E31: +2 j
B32: Formation et déploiement | C32: 5 j (combiné avec support) | D32: 3 j | E32: ajusté
B33: Hypercare post-déploiement | C33: inclus dans 5 j | D33: 3 j sur 2 sem. | E33: explicité

Sheet Détail
B2: Détail des tâches par phase
B3: Le coût se met à jour automatiquement quand le TJM est saisi dans l'onglet Synthèse (cellule C10).
B5: Réf | C5: Tâche | D5: Jours-homme | E5: Coût
B6: 1. Cadrage et conception | D6: =SUM(D7:D10) -> 4 | E6: =D6*Synthèse!$C$10 -> 0
B7: 1.1 | C7: Atelier métier ALTERRA (processus, règles, cas particuliers) | D7: 1.5 | E7: =D7*Synthèse!$C$10 -> 0
B8: 1.2 | C8: Modélisation des données et règles de gestion | D8: 1 | E8: =D8*Synthèse!$C$10 -> 0
B9: 1.3 | C9: Architecture technique et plan de tests | D9: 0.5 | E9: =D9*Synthèse!$C$10 -> 0
B10: 1.4 | C10: Maquettes Airtable Interfaces (Admin, Chef de Site) | D10: 1 | E10: =D10*Synthèse!$C$10 -> 0
B11: 2. Configuration Airtable | D11: =SUM(D12:D17) -> 7 | E11: =D11*Synthèse!$C$10 -> 0
B12: 2.1 | C12: Création des 4 tables, champs typés, formules | D12: 1.5 | E12: =D12*Synthèse!$C$10 -> 0
B13: 2.2 | C13: Vues métier (par site, par semaine, statuts) et permissions par rôle | D13: 1 | E13: =D13*Synthèse!$C$10 -> 0
B14: 2.3 | C14: Airtable Interface Admin (back-office complet) | D14: 1.5 | E14: =D14*Synthèse!$C$10 -> 0
B15: 2.4 | C15: Airtable Interface Chef de Site (validation pointages) | D15: 1.5 | E15: =D15*Synthèse!$C$10 -> 0
B16: 2.5 | C16: Automatisations (notifications, mises à jour de statut, alertes) | D16: 1 | E16: =D16*Synthèse!$C$10 -> 0
B17: 2.6 | C17: Tableaux de bord (vues filtrées et Interface dashboard) | D17: 0.5 | E17: =D17*Synthèse!$C$10 -> 0
B18: 3. Jotform et intégration | D18: =SUM(D19:D23) -> 5 | E18: =D18*Synthèse!$C$10 -> 0
B19: 3.1 | C19: Formulaires Jotform : pointage et activités | D19: 1.5 | E19: =D19*Synthèse!$C$10 -> 0
B20: 3.2 | C20: Logique conditionnelle, géolocalisation et photo obligatoire | D20: 1 | E20: =D20*Synthèse!$C$10 -> 0
B21: 3.3 | C21: Intégration Jotform → Airtable (mapping et webhook) | D21: 1 | E21: =D21*Synthèse!$C$10 -> 0
B22: 3.4 | C22: Listes synchronisées dynamiquement (travailleurs, sites) | D22: 0.5 | E22: =D22*Synthèse!$C$10 -> 0
B23: 3.5 | C23: Tests du mode offline et de la synchronisation | D23: 1 | E23: =D23*Synthèse!$C$10 -> 0
B24: 4. Données initiales et comptes utilisateurs | D24: =SUM(D25:D27) -> 2 | E24: =D24*Synthèse!$C$10 -> 0
B25: 4.1 | C25: Import des données existantes (travailleurs, sites, contrats) | D25: 1 | E25: =D25*Synthèse!$C$10 -> 0
B26: 4.2 | C26: Création des comptes utilisateurs et invitations | D26: 0.5 | E26: =D26*Synthèse!$C$10 -> 0
B27: 4.3 | C27: Configuration finale et durcissement des permissions | D27: 0.5 | E27: =D27*Synthèse!$C$10 -> 0
B28: 5. Tests et recette | D28: =SUM(D29:D31) -> 4 | E28: =D28*Synthèse!$C$10 -> 0
B29: 5.1 | C29: Tests bout en bout par rôle (Admin, Chef de Site, Agent) | D29: 1.5 | E29: =D29*Synthèse!$C$10 -> 0
B30: 5.2 | C30: Test offline réel sur 1 site pilote (hors bureau) | D30: 1 | E30: =D30*Synthèse!$C$10 -> 0
B31: 5.3 | C31: Recette ALTERRA et corrections | D31: 1.5 | E31: =D31*Synthèse!$C$10 -> 0
B32: 6. Formation et déploiement | D32: =SUM(D33:D35) -> 3 | E32: =D32*Synthèse!$C$10 -> 0
B33: 6.1 | C33: Formation des Administrateurs et Chefs de Site | D33: 1 | E33: =D33*Synthèse!$C$10 -> 0
B34: 6.2 | C34: Formation des Agents Terrain (1 site pilote) | D34: 1 | E34: =D34*Synthèse!$C$10 -> 0
B35: 6.3 | C35: Mise en production et documentation utilisateur | D35: 1 | E35: =D35*Synthèse!$C$10 -> 0
B36: 7. Hypercare | D36: =SUM(D37) -> 3 | E36: =D36*Synthèse!$C$10 -> 0
B37: 7.1 | C37: Support et corrections en hypercare (sur 2 semaines) | D37: 3 | E37: =D37*Synthèse!$C$10 -> 0
B38: TOTAL GÉNÉRAL | D38: =Synthèse!C21 -> 28 | E38: =D38*Synthèse!$C$10 -> 0
B41: Légende couleurs
B42: Bleu | C42: Saisie modifiable (j-h, TJM)
B43: Noir | C43: Formule de calcul
B44: Vert | C44: Lien vers un autre onglet
...

Sheet Hypothèses
B2: Hypothèses, périmètre et conditions
B4: PÉRIMÈTRE
B5: Sites | C5: 1 site pilote (extension à d'autres sites = devis additionnel)
B6: Travailleurs | C6: Jusqu'à 50 travailleurs actifs au démarrage
B7: Utilisateurs Airtable | C7: 1 Administrateur + 2 à 4 Chefs de Site
B8: Formulaires Jotform | C8: 1 formulaire de pointage + 1 formulaire d'enregistrement travailleur (à confirmer en atelier)
B9: Langues | C9: Interface en français ; libellés courts en malagasy possibles
B11: HYPOTHÈSES TECHNIQUES
B12: Stack | C12: Airtable (Team) + Jotform Mobile Forms
B13: Authentification Agents | C13: Saisie déclarative via dropdown synchronisée avec Airtable (pas de compte individuel)
B14: Anti-fraude | C14: Photo obligatoire + géolocalisation à chaque pointage
B15: Mode hors ligne | C15: Jotform Mobile App côté Agent ; Chef de Site en mode connecté ou validation différée
B16: Hébergement | C16: Airtable (US/EU selon plan) ; Jotform (US par défaut)
B18: INCLUS DANS LE CHIFFRAGE
B19: Cadrage | C19: Atelier métier, modélisation, maquettes Interface
B20: Configuration | C20: Tables, vues, permissions, automatisations, Interfaces, dashboards
B21: Intégration | C21: Jotform → Airtable, listes synchronisées, tests offline
B22: Migration | C22: Import des données existantes (1 jeu de données fourni au format CSV/Excel propre)
B23: Recette | C23: Tests bout en bout + 1 itération de corrections
B24: Formation | C24: Admin/Chef de Site (1 j) + Agents 1 site (1 j)
B25: Hypercare | C25: 3 j de support post-mise en production sur 2 semaines
B27: NON INCLUS
B28: Licences | C28: Abonnements Airtable et Jotform à la charge d'ALTERRA (cf. onglet Licences)
B29: Données | C29: Nettoyage de fichiers de données mal structurés
B30: Multi-sites | C30: Déploiement au-delà du site pilote (ajouter ~3 j par site supplémentaire)
B31: Évolutions | C31: Évolutions fonctionnelles post-recette (chiffrées en sus)
B32: Support long terme | C32: Maintenance évolutive après l'hypercare (forfait mensuel à proposer séparément)
B33: Matériel | C33: Téléphones / tablettes des Agents et Chefs de Site
B34: Connectivité | C34: Forfaits data / Wi-Fi pour le déploiement
B36: CONDITIONS DE RÉUSSITE
B37: Disponibilité ALTERRA | C37: Référent métier disponible 0,5 j/sem pendant le projet
B38: Données initiales | C38: Liste des travailleurs et sites fournie au format Excel propre en début de phase 4
B39: Validation | C39: Recette en moins de 3 jours après livraison phase 5
B41: RISQUES IDENTIFIÉS
B42: Mode offline Chef de Site | C42: Si validation hors ligne strictement requise, prévoir +2 j (workaround)
B43: Comptes Jotform individuels | C43: Si auth nominative requise pour les Agents, prévoir +1 à 2 j et coût licences
B44: Multi-formulaires | C44: Si plus de 2 formulaires Jotform requis, ajouter 0,5 à 1 j par formulaire

Sheet Licences
B2: Licences récurrentes — estimation
B3: Tarifs publics constatés en avril 2026, à confirmer auprès des éditeurs. Hors taxes locales.
B5: Outil | C5: Plan | D5: Nb licences | E5: Prix unitaire (USD/mois) | F5: Coût mensuel (USD) | G5: Coût annuel (USD)
B6: Airtable | C6: Team (recommandé) | D6: 4 | E6: 24 | F6: =D6*E6 -> 96 | G6: =F6*12 -> 1152
B7: Jotform | C7: Bronze ou Silver | D7: 1 | E7: 39 | F7: =D7*E7 -> 39 | G7: =F7*12 -> 468
B8: Make (option) | C8: Core | D8: 1 | E8: 9 | F8: =D8*E8 -> 9 | G8: =F8*12 -> 108
B9: Total | C9: (option Make incluse) | F9: =SUM(F6:F8) -> 144 | G9: =F9*12 -> 1728
B12: Notes détaillées par outil
B13: Airtable Team
B14: 24 USD/utilisateur/mois facturé annuellement (29 USD en mensuel). Inclut : 50 000 records par base, 100 GB de pièces jointes, 25 000 automatisations/mois, Interfaces, permissions par rôle. Suffit pour un démarrage avec 1 site et ~50 travailleurs.
B15: Airtable — passage Business
B16: À envisager au-delà de 50 000 records cumulés (pointages × travailleurs × jours). À ~20 pointages/travailleur/mois × 50 travailleurs × 12 mois = 12 000 records/an : large marge en Team pendant 3 ans.
B17: Jotform Bronze (39 USD/mois)
B18: 100 soumissions/mois, 100 MB stockage, suffit pour un test. Pour prod réelle, prévoir Silver (49 USD/mois) ou Gold (129 USD/mois) selon volume de pointages.
B19: Jotform Mobile Forms
B20: Inclus dans tous les plans payants, supporte le mode hors ligne sur Android.
B21: Comptes Agents Jotform
B22: Non inclus : si authentification individuelle des Agents souhaitée, chaque Agent compte comme un seat → multiplier le coût Jotform par le nombre d'Agents.
B23: Make (option)
B24: Plan Core à 9 USD/mois, 10 000 opérations/mois. Optionnel : à activer seulement si besoin d'automatisations dépassant les capacités d'Airtable Automations.
