Workbook

Sheet Synthèse
B2: Chiffrage et macroplanning — Plateforme ALTERRA v3
B3: Livraison en 2 phases : V1 (cœur, 50 j-h, 12 sem) puis V2 (extensions terrain, 20 j-h, 4-5 sem)
B5: Version | C5: v3.0 — V1 + V2 (NFC, bio offline, workflows)
B6: Date | C6: 28 avril 2026
B7: Périmètre | C7: 5 sites, ~600 MOC actifs, 21 utilisateurs (1 Admin + 5 Chef Service + 15 Chef Équipe)
B9: Hypothèse de calcul
B10: TJM (Taux Journalier Moyen) | C10: 0 | E10: à renseigner
B12: V1 — Cœur fonctionnel (12 semaines)
B13: Phase | C13: Jours-homme | D13: % V1 | E13: Coût (TJM × j-h)
B14: 1. Cadrage et conception | C14: 4 | D14: =C14/$C$25 -> 0.08 | E14: =C14*$C$10 -> 0
B15: 2. Backend socle (NestJS + Prisma) | C15: 4 | D15: =C15/$C$25 -> 0.08 | E15: =C15*$C$10 -> 0
B16: 3. API métier V1 | C16: 6 | D16: =C16/$C$25 -> 0.12 | E16: =C16*$C$10 -> 0
B17: 4. Frontend Admin V1 (Web App) | C17: 7 | D17: =C17/$C$25 -> 0.14 | E17: =C17*$C$10 -> 0
B18: 5. PWA Terrain V1 (offline-first, sans NFC ni bio offline) | C18: 8 | D18: =C18/$C$25 -> 0.16 | E18: =C18*$C$10 -> 0
B19: 6. Module biométrie V1 + rapports | C19: 4 | D19: =C19/$C$25 -> 0.08 | E19: =C19*$C$10 -> 0
B20: 7. Données initiales V1 + déploiement | C20: 2 | D20: =C20/$C$25 -> 0.04 | E20: =C20*$C$10 -> 0
B21: 8. Tests et recette V1 | C21: 4 | D21: =C21/$C$25 -> 0.08 | E21: =C21*$C$10 -> 0
B22: 9. Formation et documentation V1 | C22: 2 | D22: =C22/$C$25 -> 0.04 | E22: =C22*$C$10 -> 0
B23: 10. Hypercare V1 | C23: 3 | D23: =C23/$C$25 -> 0.06 | E23: =C23*$C$10 -> 0
B24: Marge prudentielle V1 (AXIAN, MVola, UX) | C24: 6 | E24: =C24*$C$10 -> 0
B25: TOTAL V1 | C25: =SUM(C14:C24) -> 50 | E25: =C25*$C$10 -> 0
B27: V2 — Extensions terrain (NFC, biométrie offline, workflows) — 4-5 semaines
B28: Phase | C28: Jours-homme | D28: % V2 | E28: Coût (TJM × j-h)
B29: 11. Cadrage V2 (extensions terrain) | C29: 1.5 | D29: =C29/$C$39 -> 0.071428571 | E29: =C29*$C$10 -> 0
B30: 12. Hiérarchie Zone / Parcelle | C30: 2 | D30: =C30/$C$39 -> 0.095238095 | E30: =C30*$C$10 -> 0
B31: 13. Composition et gestion d'équipes | C31: 2.5 | D31: =C31/$C$39 -> 0.11904762 | E31: =C31*$C$10 -> 0
B32: 14. Pointage présence NFC | C32: 2.5 | D32: =C32/$C$39 -> 0.11904762 | E32: =C32*$C$10 -> 0
B33: 15. Biométrie offline | C33: 3 | D33: =C33/$C$39 -> 0.14285714 | E33: =C33*$C$10 -> 0
B34: 16. Workflows de demandes | C34: 3 | D34: =C34/$C$39 -> 0.14285714 | E34: =C34*$C$10 -> 0
B35: 17. Cartographie Admin | C35: 1.5 | D35: =C35/$C$39 -> 0.071428571 | E35: =C35*$C$10 -> 0
B36: 18. Clôture quotidienne | C36: 1 | D36: =C36/$C$39 -> 0.047619048 | E36: =C36*$C$10 -> 0
B37: 19. Tests V2 + recette + hypercare V2 | C37: 2.5 | D37: =C37/$C$39 -> 0.11904762 | E37: =C37*$C$10 -> 0
B38: Marge prudentielle V2 (NFC, bio offline) | C38: 1.5 | E38: =C38*$C$10 -> 0
B39: TOTAL V2 | C39: =SUM(C29:C38) -> 21 | E39: =C39*$C$10 -> 0
B41: TOTAL V1 + V2 | C41: =C25+C39 -> 71 | E41: =C41*$C$10 -> 0
B43: Stratégie V1+V2 : V1 livre un système de pointage et de paiement opérationnel en 12 semaines (objectif 50 j-h tenu). V2 ajoute NFC, biométrie offline, workflows et hiérarchie Zone/Parcelle en 4-5 semaines supplémentaires (20 j-h). V2 peut être signée séparément après recette V1.
B45: Délai calendaire
B46: V1 — Cœur fonctionnel | C46: 12 semaines (S1 à S12)
B47: V2 — Extensions terrain | C47: 5 semaines (S13 à S17)
B48: V1 + V2 enchaînés | C48: 17 semaines totales
...

Sheet Détail V1
B2: V1 — Détail des tâches par phase (cœur fonctionnel)
B3: Le coût se met à jour automatiquement quand le TJM est saisi dans l'onglet Synthèse (cellule C10).
B5: Réf | C5: Tâche | D5: Jours-homme | E5: Coût
B6: 1. Cadrage et conception | D6: =SUM(D7:D9) -> 4 | E6: =D6*Synthèse!$C$10 -> 0
B7: 1.1 | C7: Atelier métier ALTERRA (workflow MOC, activités, biométrie, paiement) | D7: 1.5 | E7: =D7*Synthèse!$C$10 -> 0
B8: 1.2 | C8: Spec détaillée + user stories par rôle (Admin, Chef de Service, Chef d'Équipe) | D8: 1 | E8: =D8*Synthèse!$C$10 -> 0
B9: 1.3 | C9: Maquettes Figma — écrans clés Web Admin et PWA Terrain V1 | D9: 1.5 | E9: =D9*Synthèse!$C$10 -> 0
B10: 2. Backend socle (NestJS + Prisma) | D10: =SUM(D11:D14) -> 4 | E10: =D10*Synthèse!$C$10 -> 0
B11: 2.1 | C11: Setup Node.js + NestJS + Prisma + PostgreSQL + Docker Compose | D11: 1 | E11: =D11*Synthèse!$C$10 -> 0
B12: 2.2 | C12: Schéma de données V1 (Prisma) et migrations | D12: 1 | E12: =D12*Synthèse!$C$10 -> 0
B13: 2.3 | C13: Authentification JWT + refresh + récupération mot de passe | D13: 1.5 | E13: =D13*Synthèse!$C$10 -> 0
B14: 2.4 | C14: RBAC + audit log via triggers PostgreSQL + middleware permissions | D14: 0.5 | E14: =D14*Synthèse!$C$10 -> 0
B15: 3. API métier V1 | D15: =SUM(D16:D19) -> 6 | E15: =D15*Synthèse!$C$10 -> 0
B16: 3.1 | C16: CRUD référentiels (Sites, Activités) | D16: 1.5 | E16: =D16*Synthèse!$C$10 -> 0
B17: 3.2 | C17: CRUD Travailleurs + import CSV/Excel | D17: 1.5 | E17: =D17*Synthèse!$C$10 -> 0
B18: 3.3 | C18: API Pointages : création, sync batch idempotent, validation, correction | D18: 2 | E18: =D18*Synthèse!$C$10 -> 0
B19: 3.4 | C19: API Paiements : calcul bordereau + génération fichier Excel MVola | D19: 1 | E19: =D19*Synthèse!$C$10 -> 0
B20: 4. Frontend Admin V1 (Web App) | D20: =SUM(D21:D26) -> 7 | E20: =D20*Synthèse!$C$10 -> 0
B21: 4.1 | C21: Setup React + Vite + auth + navigation + design system shadcn/ui | D21: 1 | E21: =D21*Synthèse!$C$10 -> 0
B22: 4.2 | C22: Tableau de bord (KPIs, graphes, alertes) | D22: 1 | E22: =D22*Synthèse!$C$10 -> 0
B23: 4.3 | C23: Modules référentiels (Sites, Activités, Travailleurs, Utilisateurs) | D23: 1.5 | E23: =D23*Synthèse!$C$10 -> 0
B24: 4.4 | C24: Module Pointages — consultation, filtres, correction unitaire | D24: 1.5 | E24: =D24*Synthèse!$C$10 -> 0
B25: 4.5 | C25: Module Paiements — bordereau, génération Excel MVola, suivi statuts | D25: 1.5 | E25: =D25*Synthèse!$C$10 -> 0
B26: 4.6 | C26: Reporting, exports CSV/Excel/PDF, vue Audit log | D26: 0.5 | E26: =D26*Synthèse!$C$10 -> 0
B27: 5. PWA Terrain V1 (offline-first, sans NFC ni bio offline) | D27: =SUM(D28:D31) -> 8 | E27: =D27*Synthèse!$C$10 -> 0
B28: 5.1 | C28: Setup PWA + Service Worker + Dexie + auth avec cache offline | D28: 1.5 | E28: =D28*Synthèse!$C$10 -> 0
B29: 5.2 | C29: Mode Chef d'Équipe : sélection activité + écran saisie en lot ~40 MOC | D29: 3 | E29: =D29*Synthèse!$C$10 -> 0
B30: 5.3 | C30: Mode Chef de Service : validation hebdo + capture photo biométrique online | D30: 1.5 | E30: =D30*Synthèse!$C$10 -> 0
B31: 5.4 | C31: Sync engine : push batch idempotent, gestion conflits, retry | D31: 2 | E31: =D31*Synthèse!$C$10 -> 0
B32: 6. Module biométrie V1 + rapports | D32: =SUM(D33:D35) -> 4 | E32: =D32*Synthèse!$C$10 -> 0
B33: 6.1 | C33: Microservice biométrie : adapter pattern (mock + manuel + AxianProvider) | D33: 1 | E33: =D33*Synthèse!$C$10 -> 0
B34: 6.2 | C34: Intégration API AXIAN online (appels, retry, gestion erreurs) | D34: 1 | E34: =D34*Synthèse!$C$10 -> 0
B35: 6.3 | C35: Génération rapport hebdomadaire + facture PDF avec signature électronique | D35: 2 | E35: =D35*Synthèse!$C$10 -> 0
B36: 7. Données initiales V1 + déploiement | D36: =SUM(D37:D38) -> 2 | E36: =D36*Synthèse!$C$10 -> 0
B37: 7.1 | C37: Import des données initiales (sites, activités, MOC) au format Excel | D37: 1 | E37: =D37*Synthèse!$C$10 -> 0
B38: 7.2 | C38: Déploiement VPS Docker Compose + Nginx + TLS + backup + monitoring | D38: 1 | E38: =D38*Synthèse!$C$10 -> 0
B39: 8. Tests et recette V1 | D39: =SUM(D40:D42) -> 4 | E39: =D39*Synthèse!$C$10 -> 0
B40: 8.1 | C40: Tests bout en bout par rôle (Admin, Chef de Service, Chef d'Équipe) | D40: 1.5 | E40: =D40*Synthèse!$C$10 -> 0
B41: 8.2 | C41: Test offline réel sur 1 site pilote | D41: 1 | E41: =D41*Synthèse!$C$10 -> 0
B42: 8.3 | C42: Recette ALTERRA + corrections V1 | D42: 1.5 | E42: =D42*Synthèse!$C$10 -> 0
...

Sheet Détail V2
B2: V2 — Détail des tâches par phase (extensions terrain)
B3: NFC, biométrie offline, workflows de demandes, hiérarchie Zone/Parcelle, cartographie, clôture quotidienne.
B5: Réf | C5: Tâche | D5: Jours-homme | E5: Coût
B6: 11. Cadrage V2 (extensions terrain) | D6: =SUM(D7) -> 1.5 | E6: =D6*Synthèse!$C$10 -> 0
B7: 11.1 | C7: Atelier UX workflows demandes + spec NFC + maquettes V2 | D7: 1.5 | E7: =D7*Synthèse!$C$10 -> 0
B8: 12. Hiérarchie Zone / Parcelle | D8: =SUM(D9:D10) -> 2 | E8: =D8*Synthèse!$C$10 -> 0
B9: 12.1 | C9: Modèle de données + migrations + UI Admin (CRUD Zones / Parcelles) | D9: 1.5 | E9: =D9*Synthèse!$C$10 -> 0
B10: 12.2 | C10: Intégration Zone/Parcelle dans pointages + filtres validation | D10: 0.5 | E10: =D10*Synthèse!$C$10 -> 0
B11: 13. Composition et gestion d'équipes | D11: =SUM(D12:D13) -> 2.5 | E11: =D11*Synthèse!$C$10 -> 0
B12: 13.1 | C12: Composition équipes côté PWA Chef de Service (CRUD) | D12: 1.5 | E12: =D12*Synthèse!$C$10 -> 0
B13: 13.2 | C13: Gestion équipe locale Chef d'Équipe (ajout/retrait depuis base existante) | D13: 1 | E13: =D13*Synthèse!$C$10 -> 0
B14: 14. Pointage présence NFC | D14: =SUM(D15:D16) -> 2.5 | E14: =D14*Synthèse!$C$10 -> 0
B15: 14.1 | C15: Module NFC PWA (Web NFC API) + scan badges + UI mode lecture | D15: 1.5 | E15: =D15*Synthèse!$C$10 -> 0
B16: 14.2 | C16: Backend PresenceRecord + Badge + endpoint sync + tests appareils Android | D16: 1 | E16: =D16*Synthèse!$C$10 -> 0
B17: 15. Biométrie offline | D17: =SUM(D18:D19) -> 3 | E17: =D17*Synthèse!$C$10 -> 0
B18: 15.1 | C18: Module pré-fetch templates biométriques + chiffrement WebCrypto local | D18: 1.5 | E18: =D18*Synthèse!$C$10 -> 0
B19: 15.2 | C19: Comparaison face matching embarqué (face-api.js ou équivalent) + sync résultats | D19: 1.5 | E19: =D19*Synthèse!$C$10 -> 0
B20: 16. Workflows de demandes | D20: =SUM(D21:D23) -> 3 | E20: =D20*Synthèse!$C$10 -> 0
B21: 16.1 | C21: Demande précisions Chef de Service → Chef d'Équipe (PWA + backend) | D21: 1 | E21: =D21*Synthèse!$C$10 -> 0
B22: 16.2 | C22: Demande activité Chef de Service → Admin (PWA + Web Admin + backend) | D22: 1 | E22: =D22*Synthèse!$C$10 -> 0
B23: 16.3 | C23: Demande ajout MOC Chef de Service → Admin (PWA + Web Admin + backend) | D23: 1 | E23: =D23*Synthèse!$C$10 -> 0
B24: 17. Cartographie Admin | D24: =SUM(D25) -> 1.5 | E24: =D24*Synthèse!$C$10 -> 0
B25: 17.1 | C25: Carte Leaflet + marqueurs sites + couches Zones/Parcelles + popups | D25: 1.5 | E25: =D25*Synthèse!$C$10 -> 0
B26: 18. Clôture quotidienne | D26: =SUM(D27) -> 1 | E26: =D26*Synthèse!$C$10 -> 0
B27: 18.1 | C27: Endpoint /reports/daily + UI clôture journalière + rapport PDF journalier | D27: 1 | E27: =D27*Synthèse!$C$10 -> 0
B28: 19. Tests V2 + recette + hypercare V2 | D28: =SUM(D29:D30) -> 2.5 | E28: =D28*Synthèse!$C$10 -> 0
B29: 19.1 | C29: Tests E2E V2 + tests offline NFC + tests biométrie offline | D29: 1 | E29: =D29*Synthèse!$C$10 -> 0
B30: 19.2 | C30: Recette ALTERRA V2 + corrections + hypercare 2 semaines | D30: 1.5 | E30: =D30*Synthèse!$C$10 -> 0
B31: Sous-total V2 baseline + marge | D31: =Synthèse!C39 -> 21 | E31: =Synthèse!E39 -> 0

Sheet Macroplanning
B2: Macroplanning V1 + V2 — 17 semaines
B3: V1 en bleu (S1 à S12), V2 en rouge (S13 à S17). Équipe : 2 dev fullstack en parallèle.
B5: Phase | C5: S1 | D5: S2 | E5: S3 | F5: S4 | G5: S5 | H5: S6 | I5: S7 | J5: S8 | K5: S9 | L5: S10 | M5: S11 | N5: S12 | O5: S13 | P5: S14 | Q5: S15 | R5: S16 | S5: S17
B6: 1. Cadrage et conception
B7: 2. Backend socle
B8: 3. API métier V1
B9: 4. Frontend Admin V1
B10: 5. PWA Terrain V1
B11: 6. Biométrie V1 + rapports
B12: 7. Données + déploiement V1
B13: 8. Tests et recette V1
B14: 9. Formation + docs V1
B15: 10. Hypercare V1
B16: 11. Cadrage V2
B17: 12. Zone / Parcelle
... B25: Jalons clés
B26: Échéance | D26: Livrable
B27: Fin S1 | D27: V1 — Spec validée + maquettes Figma
B28: Fin S4 | D28: V1 — Backend + API métier opérationnels (sandbox)
B29: Fin S6 | D29: V1 — Frontend Admin fonctionnel en démo
B30: Fin S8 | D30: V1 — PWA Terrain testable bout en bout
B31: Fin S9 | D31: V1 — Module biométrique intégré (mock + manuel)
B32: Fin S10 | D32: V1 — Recette validée + formation effectuée
B33: S11-S12 | D33: V1 — Hypercare en production
B34: Décision GO V2 | D34: Après recette V1 — signature avenant V2
B35: Fin S13 | D35: V2 — Cadrage + modèle Zone/Parcelle
B36: Fin S15 | D36: V2 — NFC + Biométrie offline en démo
B37: Fin S16 | D37: V2 — Workflows demandes + Cartographie livrés
B38: Fin S17 | D38: V2 — Recette + mise en production

Sheet Marge et risques
B2: Marges prudentielles et risques V1 + V2
B3: Décomposition des marges intégrées dans le total d'engagement (V1 : 6 j-h ; V2 : 1,5 j-h).
B5: Risque / inconnu | C5: Marge (j-h) | D5: Justification
B6: Marge V1
B7: API biométrique AXIAN | C7: 2.5 | D7: API en cours de développement sans documentation. Couche d'abstraction prévue mais l'intégration finale peut prendre 1 à 3 j supplémentaires.
B8: Format MVola Bulk Transfer | C8: 1 | D8: Format précis du fichier Excel à confirmer auprès du partenariat MVola. Variations possibles sur les en-têtes, longueur de description, encodage.
B9: Saisie en lot 40 MOC (UX) | C9: 1 | D9: L'écran de saisie en lot pour ~40 travailleurs est critique pour l'adoption. Itération possible après prototype testé.
B10: Volumétrie réelle | C10: 0.5 | D10: Hypothèses validées avec ALTERRA mais quelques incertitudes sur le pic réel.
B11: Imprévus généraux V1 | C11: 1 | D11: Marge de sécurité pour debug, comportement smartphone bas de gamme, etc.
B12: Total marge V1 | C12: =SUM(C7:C11) -> 6
B14: Marge V2
B15: Web NFC API (compatibilité) | C15: 0.5 | D15: Chrome Android uniquement. Tests appareils cibles requis. Fallback saisie manuelle prévu.
B16: Biométrie offline (perf face matching) | C16: 0.5 | D16: face-api.js sur Android bas de gamme : à benchmarker. Modèle TinyFace en fallback.
B17: Workflows demandes (UX) | C17: 0.5 | D17: Risque d'UX confuse si mal designée. Maquette dédiée.
B18: Total marge V2 | C18: =SUM(C15:C17) -> 1.5
B20: Risques additionnels V2 hors marge : compatibilité NFC iOS (impossible, prévoir flotte Android uniquement), conformité RGPD/Loi 2014-038 sur stockage biométrique local (analyse juridique préalable recommandée), évolution API AXIAN avec impact face matching.

Sheet Charges complémentaires
B2: Charges complémentaires (récurrentes)
B3: Coûts opérationnels mensuels et annuels, hors prestation, à la charge d'ALTERRA. Tarifs indicatifs avril 2026.
B5: Poste | C5: Détail | D5: Mensuel (USD) | E5: Annuel (USD)
B6: VPS hébergement | C6: OVH ou Telma — 4 vCPU / 8 GB / 80 GB SSD | D6: 50 | E6: =D6*12 -> 600
B7: Domaine + DNS | C7: Renouvellement annuel (SSL Let's Encrypt gratuit) | D7: 2 | E7: =D7*12 -> 24
B8: Stockage backup externalisé | C8: Backblaze B2, ~50 GB | D8: 3 | E8: =D8*12 -> 36
B9: SMS OTP (Telma SMS API) | C9: ~200 OTP/mois pour authentification | D9: 10 | E9: =D9*12 -> 120
B10: Email transactionnel | C10: Mailgun ou similar, ~3 000 emails/mois | D10: 10 | E10: =D10*12 -> 120
B11: Monitoring externe | C11: UptimeRobot Free + Healthchecks.io Free | D11: 0 | E11: =D11*12 -> 0
B12: API biométrique AXIAN | C12: Tarif à confirmer auprès d'AXIAN — placeholder | D12: 50 | E12: =D12*12 -> 600
B13: Tuiles cartographiques (V2) | C13: OpenStreetMap gratuit ou MapTiler basic | D13: 0 | E13: =D13*12 -> 0
B14: Badges NFC (V2) | C14: Coût unique, ~0,50 USD/badge × 1 000 = 500 USD one-shot | D14: 0 | E14: =D14*12 -> 0
B15: Sous-total infra + ops récurrent (USD) | D15: =SUM(D6:D14) -> 125 | E15: =D15*12 -> 1500
B17: Option : maintenance évolutive post-hypercare
B18: Forfait 1 j/mois | C18: Évolutions légères, support niveau 2 | D18: =Synthèse!C10 -> 0 | E18: =D18*12 -> 0
B20: Notes importantes
B21: • L'API biométrique AXIAN est un placeholder. Tarif à confirmer (peut être nul en interne groupe ou tarifé par requête).
B22: • Les badges NFC sont un coût unique en V2 — pas mensuel. À acheter en amont, environ 0,50 USD par badge.
B23: • Les frais MVola (commissions de transfert) sont supportés par ALTERRA dans le cadre de ses opérations courantes — non comptés ici.
B24: • Le matériel terrain (smartphones Android avec NFC obligatoire en V2) n'est pas inclus.
B25: • Le forfait maintenance évolutive est optionnel : il couvre évolutions légères, suivi technique, support de niveau 2 après hypercare.

Sheet Hypothèses
B2: Hypothèses, périmètre, conditions de réussite
B4: PÉRIMÈTRE V1 (cœur)
B5: Sites | C5: 5 sites ALTERRA — hiérarchie Site uniquement
B6: MOC | C6: ≈ 600 actifs, jusqu'à 1 000 sur la campagne
B7: Utilisateurs | C7: 1 Admin + 5 Chefs de Service + 15 Chefs d'Équipe
B8: Modèle pointage | C8: À la tâche : quantité × tarif unitaire
B9: Biométrie V1 | C9: Online uniquement, via AXIAN + mock + manuel de secours
B10: Cycle paiement V1 | C10: Hebdomadaire, fichier Excel MVola
B12: PÉRIMÈTRE V2 (extensions terrain)
B13: Hiérarchie géographique | C13: Site → Zone → Parcelle (3 niveaux)
B14: NFC | C14: Pointage de présence par scan badge NFC sur smartphone
B15: Biométrie offline | C15: Cache local chiffré + face matching embarqué
B16: Composition équipes | C16: PWA Chef de Service crée/modifie équipes
B17: Gestion équipe locale | C17: PWA Chef d'Équipe ajoute/retire membres depuis base
B18: Workflows demandes | C18: Précisions / Activité / MOC entre rôles
B19: Cartographie | C19: Carte Leaflet côté Admin
B20: Cycle paiement V2 | C20: Hebdomadaire OU quotidien (choix opérationnel)
B22: STACK TECHNIQUE
B23: Backend | C23: NestJS + Prisma + PostgreSQL 16
B24: Frontend Admin | C24: React 18 + Vite + TypeScript + shadcn/ui + Leaflet (V2)
B25: Frontend PWA | C25: React 18 + Vite + vite-plugin-pwa + Dexie.js + Web NFC API (V2)
B26: Biométrie PWA | C26: face-api.js ou équivalent embarqué léger (V2)
B27: Hébergement | C27: VPS Linux dédié à ALTERRA, Docker Compose
B29: INCLUS DANS CHIFFRAGE V1+V2
B30: Cadrage | C30: Atelier métier, spec, maquettes Figma (V1 et V2)
B31: Backend | C31: API REST complète, modèle de données, auth, audit log
B32: Frontend Admin | C32: Web App complète (V1) + cartographie + validation demandes (V2)
B33: PWA Terrain | C33: Modes Chef d'Équipe et Chef de Service avec offline-first
B34: Modules | C34: Excel MVola, PDF rapports/factures, biométrie adapter, NFC, workflows
B35: Migration | C35: Import des données initiales au format Excel propre
B36: Recette | C36: Tests bout en bout V1 et V2 + corrections
B37: Formation | C37: Admin + Chefs (V1 puis V2 si signée)
B38: Hypercare | C38: 3 semaines après V1 + 2 semaines après V2
B40: NON INCLUS
B41: Charges récurrentes | C41: VPS, services tiers (cf. onglet Charges complémentaires)
B42: Stabilisation AXIAN finale | C42: 3-5 j en sus si API livrée après V2
B43: Module MVola par API | C43: Au-delà de l'Excel, toute intégration MVola par API à chiffrer
B44: Maintenance long terme | C44: Forfait mensuel post-hypercare à chiffrer séparément
B45: Matériel et data | C45: Smartphones Android NFC, badges NFC, forfaits data
B46: Analyse RGPD V2 | C46: Analyse juridique sur stockage biométrique local (option recommandée)
...
