Workbook

Sheet Backlog
A1: Use Case | B1: User Story | C1: Acteur | D1: Tâche principale | E1: Description | F1: Estim. UI / Frontend (j/h) | G1: Estim. Backend / Logique (j/h) | H1: Total (j/h)
A2: ━━━ SECTION A — FRONTEND (React 18 · TypeScript · Vite · Tailwind CSS) ━━━
A3: Module FE-0 — Setup & Infrastructure Frontend
A4: UC-FE-SETUP | B4: Init Vite + React + TypeScript + ESLint + Prettier (path aliases, tsconfig strict) | C4: Développeur | D4: Config projet | E4: Scaffolding vite@7, @vitejs/plugin-react, typescript-eslint 9, path aliases @/ → src/, .env.local VITE_API_URL | F4: 0.25 | G4: 0.25 | H4: =F4+G4 -> 0.5
A5: UC-FE-SETUP | B5: Thème Tailwind CSS personnalisé + composants atomiques (Button, Card, Input, MadarailLogo) | C5: Développeur | D5: Design system | E5: Palette madarail (navy #0A2341, red #E30613, rail #F4F8FB), variantes Button primary/secondary, Card + titre, Input + label, SVG logo inline | F5: 0.5 | G5: 0 | H5: =F5+G5 -> 0.5
A6: UC-FE-SETUP | B6: Architecture AppContext (Context API, currentUser en mémoire, currentView, isOnline) | C6: Développeur | D6: État global | E6: useAppContext hook, état : currentUser (mémoire — jamais localStorage), currentView + guards, isOnline via window.addEventListener online/offline | F6: 0 | G6: 0.5 | H6: =F6+G6 -> 0.5
A7: UC-FE-SETUP | B7: Config PWA : vite-plugin-pwa, manifest.json, Service Worker Workbox, mode standalone | C7: Développeur | D7: PWA | E7: manifest thème madarail navy, icônes 192/512px, stratégie Network-First API, Cache-First assets statiques, installable Android/iOS | F7: 0 | G7: 0.5 | H7: =F7+G7 -> 0.5
A8: Sous-total Module FE-0 — Setup & Infrastructure Frontend | F8: =SUM(F4:F7) -> 0.75 | G8: =SUM(G4:G7) -> 1.25 | H8: =SUM(H4:H7) -> 2
A9: Module FE-1 — Authentification (UI + gestion tokens JWT)
A10: UC-FE-AUTH | B10: Page connexion (email/mot de passe, logo Madarail, messages d'erreur traduits) | C10: Agent / Admin | D10: Formulaire login | E10: Champs email + mdp, logo SVG MadarailLogo centré, gestion erreurs API (401 invalid credentials), états loading | F10: 0.25 | G10: 0.25 | H10: =F10+G10 -> 0.5
A11: UC-FE-AUTH | B11: Gestion tokens JWT : accessToken en mémoire + intercepteur Axios refresh (401 → POST /auth/refresh → retry) | C11: Agent / Admin | D11: JWT client | E11: Instance axios avec Authorization: Bearer, intercepteur response : 401 → appel /auth/refresh (cookie httpOnly envoyé auto) → mise à jour accessToken → retry requête originale | F11: 0 | G11: 0.75 | H11: =F11+G11 -> 0.75
A12: UC-FE-AUTH | B12: Guards frontend + redirections post-login par rôle (admin→dashboard, agent→pos, contrôleur→sales) | C12: Agent / Admin | D12: Guards & routing | E12: currentView initialisé selon role à la connexion, guards bloquant accès non autorisé, redirect vers vue de fallback définie par rôle | F12: 0 | G12: 0.25 | H12: =F12+G12 -> 0.25
A13: UC-FE-AUTH | B13: Logout : POST /auth/logout (révocation refresh token) + nettoyage état React | C13: Agent / Admin | D13: Déconnexion | E13: Appel POST /auth/logout, mise à null de currentUser et accessToken, retour à l'écran de connexion | F13: 0 | G13: 0.25 | H13: =F13+G13 -> 0.25
A14: Sous-total Module FE-1 — Authentification | F14: =SUM(F10:F13) -> 0.25 | G14: =SUM(G10:G13) -> 1.5 | H14: =SUM(H10:H13) -> 1.75
A15: Module FE-2 — Layout & Navigation
A16: UC-FE-NAV | B16: Sidebar responsive : desktop fixe rétractable (localStorage), mobile tiroir overlay + animation | C16: Tous | D16: Sidebar | E16: lg:fixed, overlay mobile fond semi-transparent, animation translate-x, état collapsed persisté "madarail-sidebar-collapsed", logo + badge version | F16: 0.75 | G16: 0.25 | H16: =F16+G16 -> 1
A17: UC-FE-NAV | B17: Menu filtré par rôle (7 items admin / 5 agent / 3 contrôleur) + surlignage item actif | C17: Tous | D17: Menu par rôle | E17: menuItems[] avec propriété roles[], filtre visibleItems, highlight currentView, icônes Lucide React | F17: 0 | G17: 0.25 | H17: =F17+G17 -> 0.25
A18: UC-FE-NAV | B18: Header mobile (hamburger, titre vue courante, badge OfflineIndicator compact) | C18: Tous | D18: Header mobile | E18: Barre top fixe < 1024px, icône WifiOff amber si !isOnline, titre dynamique par currentView | F18: 0.25 | G18: 0 | H18: =F18+G18 -> 0.25
A19: Sous-total Module FE-2 — Layout & Navigation | F19: =SUM(F16:F18) -> 1 | G19: =SUM(G16:G18) -> 0.5 | H19: =SUM(H16:H18) -> 1.5
A20: Module FE-3 — Couche API client (Axios + hooks + SSE)
A21: UC-FE-API | B21: Instance Axios : baseURL VITE_API_URL, headers Authorization Bearer, gestion erreurs normalisée | C21: Développeur | D21: Config Axios | E21: Singleton axios avec baseURL, intercepteur request → inject Bearer token, intercepteur response → gestion 401 (refresh) et 403 (alert rôle) | F21: 0 | G21: 0.25 | H21: =F21+G21 -> 0.25
A22: UC-FE-API | B22: Fonctions API par entité (auth, routes, sales, reservations, users) avec types TypeScript | C22: Développeur | D22: Services API | E22: Modules api/*.ts : fonctions typées (getRoutes, createSale, createReservation, etc.), DTOs request/response alignés avec le backend NestJS | F22: 0 | G22: 0.5 | H22: =F22+G22 -> 0.5
A23: UC-FE-API | B23: Hooks data-fetching personnalisés (useRoutes, useSales, useReservations) avec état loading/error | C23: Développeur | D23: Hooks React | E23: Hooks useEffect + useState ou TanStack Query léger, cache local, refetch on focus, invalidation après mutation (vente, réservation) | F23: 0 | G23: 0.5 | H23: =F23+G23 -> 0.5
A24: UC-FE-API | B24: Hook useSSE : consommation EventSource GET /events/routes, mise à jour stock catalogue en temps réel | C24: Développeur | D24: Hook SSE | E24: new EventSource("/events/routes", {withCredentials:true}), parse événement route-updated {id, seatsAvailable}, màj catalogue sans reload, cleanup sur démontage | F24: 0 | G24: 0.5 | H24: =F24+G24 -> 0.5
A25: Sous-total Module FE-3 — Couche API client | F25: =SUM(F21:F24) -> 0 | G25: =SUM(G21:G24) -> 1.75 | H25: =SUM(H21:H24) -> 1.75
A26: Module FE-4 — Tableau de bord (admin uniquement)
A27: UC-FE-DASH | B27: KPI widgets temps réel : recettes du jour, billets vendus, transactions, panier moyen, trajets actifs | C27: Admin | D27: KPIs temps réel | E27: 5 cards avec icônes Lucide, calcul depuis GET /sales?date=today, formatAriary(), mise à jour à chaque invalidation du cache | F27: 0.5 | G27: 0.5 | H27: =F27+G27 -> 1
A28: UC-FE-DASH | B28: Top 5 trajets les plus vendus (classés par revenus décroissants — départ→arrivée, classe, qté, montant) | C28: Admin | D28: Top 5 trajets | E28: Agrégation côté frontend sur sales du jour, tri revenue DESC, tableau 5 lignes avec badge classe et formatAriary | F28: 0.25 | G28: 0.25 | H28: =F28+G28 -> 0.5
A29: UC-FE-DASH | B29: Répartition opérateurs Mobile Money (barres MVola / Orange Money / Airtel Money — nb + %) | C29: Admin | D29: Barres Mobile Money | E29: Comptage par paymentMethod, barres CSS width proportionnelle, affichage nb transactions + pourcentage | F29: 0.25 | G29: 0.25 | H29: =F29+G29 -> 0.5
A30: UC-FE-DASH | B30: Histogramme ventes par heure (revenus cumulés par tranche horaire, 0h–23h) | C30: Admin | D30: Histogramme horaire | E30: Regroupement par heure(createdAt), tableau 24 slots, barres SVG ou div height proportionnelle au revenu max de la journée | F30: 0.25 | G30: 0.25 | H30: =F30+G30 -> 0.5
A31: Sous-total Module FE-4 — Tableau de bord | F31: =SUM(F27:F30) -> 1.25 | G31: =SUM(G27:G30) -> 1.25 | H31: =SUM(H27:H30) -> 2.5
A32: Module FE-5 — POS — Vente de billets (cœur applicatif)
A33: UC-FE-POS | B33: Catalogue trajets filtré par gare d'affectation agent (GET /routes?departure=user.gare) | C33: Agent | D33: Catalogue filtré | E33: Admin voit tout (pas de filtre), agent filtre departure. Grille responsive : 1 col <640px, 2 tablette, 3 ≥1280px. Trajets complets (0 place) grisés en bas. | F33: 0.75 | G33: 0.25 | H33: =F33+G33 -> 1
A34: UC-FE-POS | B34: Filtres catalogue : service commercial, code ligne (TCE/TA/MOR), recherche textuelle debounce 300ms | C34: Agent | D34: Filtres POS | E34: Dropdowns service (Tous / Train voyageur / Micheline Viko Viko / Trans Lémurie Express) et ligne, input debounce, compteur résultats visibles | F34: 0.5 | G34: 0.25 | H34: =F34+G34 -> 0.75
A35: UC-FE-POS | B35: Carte trajet : badge statut Disponible ≥10 (vert) / Stock faible 1–9 (orange) / Complet 0 (rouge + désactivé) | C35: Agent | D35: TrainCard | E35: Badge coloré mis à jour par SSE, serviceName + trainNumber, départ→arrivée, horaires, durée, operatingDays, classe, prix Ar | F35: 0.5 | G35: 0.25 | H35: =F35+G35 -> 0.75
A36: UC-FE-POS | B36: Formulaire passager : Nom, Prénom, CIN (obligatoires) + date de voyage (min = aujourd'hui) | C36: Agent | D36: Saisie passager | E36: Champs requis avec erreurs inline, date picker min=today, réinitialisation après "Ajouter au panier", validation avant ajout | F36: 0.25 | G36: 0.25 | H36: =F36+G36 -> 0.5
A37: UC-FE-POS | B37: Gestion du panier : ajout trajet, quantités +/−, suppression individuelle, sous-total par ligne | C37: Agent | D37: Panier | E37: Contrôle stock niveau 1 à l'ajout (qtyAlready + 1 > seatsAvailable), boutons +/- désactivés si stock insuffisant, suppression à quantité 0 | F37: 0.5 | G37: 0.5 | H37: =F37+G37 -> 1
A38: UC-FE-POS | B38: Calcul financier : Sous-total HT + TVA 20 % + Total TTC, formatage Ariary | C38: Agent | D38: Calcul TVA | E38: Σ(prix × qté), TVA = subtotal × 0.20, TTC = subtotal + tax, formatAriary() sur chaque montant, mise à jour réactive | F38: 0 | G38: 0.25 | H38: =F38+G38 -> 0.25
A39: UC-FE-POS | B39: Sélection opérateur Mobile Money (MVola / Orange Money / Airtel Money) avec bottom-sheet mobile | C39: Agent | D39: Paiement MM | E39: Boutons radio stylisés, sélection obligatoire avant validation, bottom-sheet sur mobile <640px, inline sur desktop | F39: 0.25 | G39: 0 | H39: =F39+G39 -> 0.25
A40: UC-FE-POS | B40: Validation + appel POST /sales + confirmation (toast/modal récapitulatif) | C40: Agent | D40: Finalisation vente | E40: Appel POST /sales avec les items du panier, gestion erreur 409 (stock insuffisant), toast succès avec ID vente, vidage panier | F40: 0 | G40: 0.5 | H40: =F40+G40 -> 0.5
...

Sheet Charges Complémentaires
A1: CHARGES COMPLÉMENTAIRES — MAÎTRISE D'ŒUVRE
A2: Ratios appliqués sur le total développement. Modifier le TJM (cellule jaune) pour recalculer.
A3: Poste MOE | B3: Profil | C3: TJM (€) | D3: Ratio (base 1 = codage) | G3: Total charges (j/h)
A4: Direction de projet | B4: Chef de projet | C4: =$B15 -> 100 | D4: 0.03 | G4: =D4*Backlog!H138 -> 1.3575
A5: Recette fonctionnelle | B5: Chef de projet | C5: =$B15 -> 100 | D5: 0.07 | G5: =D5*Backlog!H138 -> 3.1675
A6: Plan de test & cas de test | B6: Anal. fonctionnel | C6: =$B15 -> 100 | D6: 0.03 | G6: =D6*Backlog!H138 -> 1.3575
A7: Rédaction doc technique/API | B7: Tech Lead | C7: =$B15 -> 100 | D7: 0.02 | G7: =D7*Backlog!H138 -> 0.905
A8: Coordination technique | B8: Tech Lead | C8: =$B15 -> 100 | D8: 0.03 | G8: =D8*Backlog!H138 -> 1.3575
A9: Code review & qualité | B9: Tech Lead | C9: =$B15 -> 100 | D9: 0.0217 | G9: =D9*Backlog!H138 -> 0.981925
A10: Déploiements Docker & MEP | B10: DevOps | C10: =$B15 -> 100 | D10: 0.03 | G10: =D10*Backlog!H138 -> 1.3575
A11: Total ratios MOE | D11: =SUM(D4:D10) -> 0.2317 | G11: =SUM(G4:G10) -> 10.484425
A12: Total général (j/h — codage + MOE) | G12: =Backlog!H138+G11 -> 55.734425
A14: BUDGET ESTIMATIF
A15: TJM moyen (€) | B15: 100 | C15: ← Modifier pour recalculer
A16: Total j/h chargés | B16: =G12 -> 55.734425
A17: Budget HT estimé | B17: =B16*B15 -> 5573.4425
A18: TVA 20 % | B18: =B17*0.2 -> 1114.6885
A19: Budget TTC estimé | B19: =B17+B18 -> 6688.131

Sheet Macro-Planning
A1: MACRO-PLANNING — MADARAIL POS (12 semaines · 2 devs senior + Claude Code AI)
A2: Phase / Tâche | B2: S1 | C2: S2 | D2: S3 | E2: S4 | F2: S5 | G2: S6 | H2: S7 | I2: S8 | J2: S9 | K2: S10 | L2: S11 | M2: S12
A3: Phase 1 — Socle technique (Frontend + Backend en parallèle) S1–S2
A4: Init NestJS + Prisma schéma + migrations + seed | B4: =REPT("█",5) -> █████
A5: Docker Compose (postgres + api + nginx) | B5: =REPT("█",5) -> █████
A6: Init React/Vite + Tailwind + AppContext + PWA setup | B6: =REPT("█",5) -> █████
A7: Auth JWT backend (login, refresh, logout, guards) | B7: =REPT("█",5) -> █████ | C7: =REPT("█",5) -> █████
A8: Auth frontend (page login, intercepteur Axios refresh, guards vues) | C8: =REPT("█",5) -> █████
A9: Layout Sidebar responsive + OfflineIndicator | C9: =REPT("█",5) -> █████
A10: Phase 2 — API Core + POS — Caisse billets S3–S5
A11: API Trajets (GET/POST/PATCH/DELETE) + DTOs + validation | D11: =REPT("█",5) -> █████
A12: Couche API client Axios (services + hooks + SSE hook) | D12: =REPT("█",5) -> █████
A13: Catalogue POS filtré + filtres service/ligne + TrainCard | D13: =REPT("█",5) -> █████ | E13: =REPT("█",5) -> █████
A14: API Ventes (transaction Prisma atomique + décrémentation stock) | E14: =REPT("█",5) -> █████
A15: Panier + formulaire passager + calcul TVA + sélection Mobile Money | E15: =REPT("█",5) -> █████ | F15: =REPT("█",5) -> █████
A16: Validation POST /sales + gestion erreur 409 + confirmation | F16: =REPT("█",5) -> █████
A17: Phase 3 — Réservation, SeatMap & Temps réel S5–S7
A18: API Réservations (SELECT FOR UPDATE, no-show, reassign) | F18: =REPT("█",5) -> █████ | G18: =REPT("█",5) -> █████
A19: SeatMap composant + buildSeatGrid 3 configs (88/52/20 places) | F19: =REPT("█",5) -> █████ | G19: =REPT("█",5) -> █████
A20: Flow réservation 4 étapes + POST /reservations + erreur 409 | G20: =REPT("█",5) -> █████
A21: SSE backend (EventEmitter2 + @Sse endpoint + heartbeat) | G21: =REPT("█",5) -> █████ | H21: =REPT("█",5) -> █████
A22: Réattribution siège (no-show → SeatMap → reassign) | H22: =REPT("█",5) -> █████
A23: Phase 4 — Dashboard, Historique & Administration S7–S9
A24: Tableau de bord (KPIs du jour, Top 5, barres Mobile Money, histogramme) | H24: =REPT("█",5) -> █████ | I24: =REPT("█",5) -> █████
A25: Historique des ventes (tableau, modal détail, export CSV) | I25: =REPT("█",5) -> █████
A26: API Utilisateurs (CRUD) + CRUD utilisateurs frontend | I26: =REPT("█",5) -> █████ | J26: =REPT("█",5) -> █████
A27: CRUD Trajets frontend (tableau, filtres, formulaire, suppression) | J27: =REPT("█",5) -> █████
A28: Bluetooth simulation (états animés, compteurs ventes/réservations) | J28: =REPT("█",5) -> █████
A29: Phase 5 — Mode hors-ligne, Tests & Documentation S9–S11
A30: PWA : SW Workbox + cache IndexedDB trajets + queue ventes offline | J30: =REPT("█",5) -> █████ | K30: =REPT("█",5) -> █████
A31: Tests E2E NestJS (Supertest : auth, transaction vente, anti-conflit) | K31: =REPT("█",5) -> █████
A32: Documentation Swagger/OpenAPI (@nestjs/swagger) | K32: =REPT("█",5) -> █████
A33: Tests unitaires Vitest + tests composants RTL (frontend) | K33: =REPT("█",5) -> █████ | L33: =REPT("█",5) -> █████
A34: Audit responsive (375/768/1280px) + accessibilité axe-core + Lighthouse | L34: =REPT("█",5) -> █████
A35: Phase 6 — Recette fonctionnelle & Mise en production S11–S12
A36: Recette fonctionnelle (scénarios POS, réservation, hors-ligne) | L36: =REPT("█",5) -> █████ | M36: =REPT("█",5) -> █████
A37: Corrections post-recette | M37: =REPT("█",5) -> █████
A38: Déploiement Docker production + configuration HTTPS (nginx + Certbot) | M38: =REPT("█",5) -> █████
A40: Capacité estimée : ~3 j/h par développeur par semaine | Frontend : Dev 1 (spécialiste React/TypeScript) | Backend : Dev 2 (spécialiste NestJS/PostgreSQL) | Phases 5 & 6 : convergence des deux devs
